# サンプルアプリ作成④

## ✅ 行ったこと

- ルーティングの定義

## ルーティング（ URL と処理の紐付け）
ルーティングとは**URLと処理の紐付け**です。

つまり http://127.0.0.1:8000/sample_app/post/create/ にアクセスした時には、<br>
View の create_post() を呼び出す...みたいなのを定義してあげます。<br>
今回は以下のような紐付けにします。

- データ作成: http://127.0.0.1:8000/sample_app/post/create/
- データ編集: http://127.0.0.1:8000/sample_app/post/edit/1/
- データ一覧: http://127.0.0.1:8000/sample_app/post/
- データ削除: http://127.0.0.1:8000/sample_app/post/delete/1/

my_project/sample_app/urls.py というファイルを作成
```
from django.urls import path
from sample_app import views


app_name = 'sample_app'
urlpatterns = [
    path('post/create/', views.create_post, name='create_post'),  # 作成
    path('post/edit/<int:post_id>/', views.edit_post, name='edit_post'),  # 修正
    path('post/', views.read_post, name='read_post'),   # 一覧表示
    path('post/delete/<int:post_id>/', views.delete_post, name='delete_post'),   # 削除
]
```
次に、作成した my_project/sample_app/urls.py をプロジェクト全体の my_project/urls.py で読み込む
```
from django.contrib import admin
from django.urls import path, include   # Add


urlpatterns = [
    path('sample_app/', include('sample_app.urls')),   # Add
    path('admin/', admin.site.urls),
]
```
こうすることで、プロジェクトがアプリケーションURLを認識してくれるようになる<br>
name='XXX' は何でも良い（例は関数名と揃えるようにしている）

## 完成
python manage.py runserver を実行してみる
```
tokunaganaoya@tokunaganaoyanoMacBook-Pro my_project % python manage.py runserver 
Watching for file changes with StatReloader
Performing system checks...

Exception in thread django-main-thread:
Traceback (most recent call last):
  File "/Users/tokunaganaoya/.pyenv/versions/3.10.4/lib/python3.10/threading.py", line 1009, in _bootstrap_inner
    self.run()
  File "/Users/tokunaganaoya/.pyenv/versions/3.10.4/lib/python3.10/threading.py", line 946, in run
    self._target(*self._args, **self._kwargs)
  File "/Users/tokunaganaoya/.pyenv/versions/3.10.4/lib/python3.10/site-packages/django/utils/autoreload.py", line 64, in wrapper
    fn(*args, **kwargs)
  File "/Users/tokunaganaoya/.pyenv/versions/3.10.4/lib/python3.10/site-packages/django/core/management/commands/runserver.py", line 134, in inner_run
    self.check(**check_kwargs)
  File "/Users/tokunaganaoya/.pyenv/versions/3.10.4/lib/python3.10/site-packages/django/core/management/base.py", line 492, in check
    all_issues = checks.run_checks(
  File "/Users/tokunaganaoya/.pyenv/versions/3.10.4/lib/python3.10/site-packages/django/core/checks/registry.py", line 89, in run_checks
    new_errors = check(app_configs=app_configs, databases=databases)
  File "/Users/tokunaganaoya/.pyenv/versions/3.10.4/lib/python3.10/site-packages/django/core/checks/urls.py", line 16, in check_url_config
    return check_resolver(resolver)
  File "/Users/tokunaganaoya/.pyenv/versions/3.10.4/lib/python3.10/site-packages/django/core/checks/urls.py", line 26, in check_resolver
    return check_method()
  File "/Users/tokunaganaoya/.pyenv/versions/3.10.4/lib/python3.10/site-packages/django/urls/resolvers.py", line 531, in check
    for pattern in self.url_patterns:
  File "/Users/tokunaganaoya/.pyenv/versions/3.10.4/lib/python3.10/site-packages/django/utils/functional.py", line 47, in __get__
    res = instance.__dict__[self.name] = self.func(instance)
  File "/Users/tokunaganaoya/.pyenv/versions/3.10.4/lib/python3.10/site-packages/django/urls/resolvers.py", line 718, in url_patterns
    patterns = getattr(self.urlconf_module, "urlpatterns", self.urlconf_module)
  File "/Users/tokunaganaoya/.pyenv/versions/3.10.4/lib/python3.10/site-packages/django/utils/functional.py", line 47, in __get__
    res = instance.__dict__[self.name] = self.func(instance)
  File "/Users/tokunaganaoya/.pyenv/versions/3.10.4/lib/python3.10/site-packages/django/urls/resolvers.py", line 711, in urlconf_module
    return import_module(self.urlconf_name)
  File "/Users/tokunaganaoya/.pyenv/versions/3.10.4/lib/python3.10/importlib/__init__.py", line 126, in import_module
    return _bootstrap._gcd_import(name[level:], package, level)
  File "<frozen importlib._bootstrap>", line 1050, in _gcd_import
  File "<frozen importlib._bootstrap>", line 1027, in _find_and_load
  File "<frozen importlib._bootstrap>", line 1006, in _find_and_load_unlocked
  File "<frozen importlib._bootstrap>", line 688, in _load_unlocked
  File "<frozen importlib._bootstrap_external>", line 883, in exec_module
  File "<frozen importlib._bootstrap>", line 241, in _call_with_frames_removed
  File "/Users/tokunaganaoya/my_project/my_project/urls.py", line 21, in <module>
    path('sample_app/', include('sample_app.urls')),
NameError: name 'include' is not defined
```

❗️エラーの発生<br>
**NameError: name 'include' is not defined**
👉 Django に include を使ってるのに、インポートしていない というエラー(GPT)

エラーの原因(修正前)
```
from django.contrib import admin
from django.urls import path

urlpatterns = [
    path('sample_app/', include('sample_app.urls')),
    path('admin/', admin.site.urls),
]
```
from django.urls import pathの部分に, includeを書き忘れ<br>
書いた結果
```
/Users/tokunaganaoya/my_project/my_project/urls.py changed, reloading.
Watching for file changes with StatReloader
Performing system checks...

System check identified no issues (0 silenced).
July 22, 2025 - 16:19:13
Django version 5.2.4, using settings 'my_project.settings'
Starting development server at http://127.0.0.1:8000/
Quit the server with CONTROL-C.

WARNING: This is a development server. Do not use it in a production setting. Use a production WSGI or ASGI server instead.
For more information on production servers see: https://docs.djangoproject.com/en/5.2/howto/deployment/
[22/Jul/2025 16:19:28] "GET /sample_app/post/ HTTP/1.1" 200 345
```
起動確認！<br>
[![Image from Gyazo](https://i.gyazo.com/eb558ab8f805dde81155849240875e67.png)](https://gyazo.com/eb558ab8f805dde81155849240875e67)

## 参考サイト
[1](https://qiita.com/pythonista/items/19613663ef7bb3c57d4f#%E3%83%AB%E3%83%BC%E3%83%86%E3%82%A3%E3%83%B3%E3%82%B0%E5%AE%9A%E7%BE%A9)